File: wraith/f201104090030.pxt.vms
VAMAS Surface Chemical Analysis Standard Data Transfer Format 1988 May 4
ALS
R4000LI-4MS241_4ES243
Ogletree
Not Specified
0
NORM
REGULAR
0
1
Slice
d
0
0
0
0
14
Survey - 590eV
PbSe-GeS Annealed
2011
4
10
7
41
2
0
7
Casa Info Follows
0
0
0
0

Lens Mode = Transmission
XPS
1

590
1e+037
1e+037
1e+037
1e+037
1e+037
FAT
100
1e+037
1e+037
1e+037
1e+037
1e+037
1e+037
1e+037
Survey - 590eV

-1
Kinetic Energy
eV
30
0.25
2
Intensity
d
Transmission
d
pulse counting
200
1e+037
0
1.30027e+006
1.28282e+006
1.2927e+006
1.26287e+006
1.24598e+006
1.25913e+006
1.21602e+006
1.17845e+006
1.17539e+006
1.14932e+006
1.12338e+006
1.11605e+006
1.09522e+006
1.08891e+006
1.07759e+006
1.06584e+006
1.05758e+006
1.02397e+006
1.02174e+006
992231
997994
986292
980947
968333
933061
929095
894916
894625
862742
854611
820636
824626
807557
776531
777548
752783
744175
733188
713923
696570
684341
677907
668649
686022
683171
678426
702961
829525
940019
761012
626699
596435
579552
574840
577098
578988
652622
798113
999543
1.12552e+006
1.04792e+006
858716
706799
635339
622995
647639
849396
921426
633089
505979
485179
473868
453974
455536
445603
449740
447046
435666
439164
436160
433367
427593
425938
420847
425079
418386
413068
416599
417772
407523
411308
408245
403331
398725
405526
393512
391275
392521
389582
384938
387161
376772
372853
375038
375067
373445
363956
362784
365025
369242
358692
360117
366859
374942
386436
393664
384169
385363
375606
374366
374770
379250
379468
373985
366845
360821
357127
352004
339344
337849
331619
330822
327286
324574
315806
317262
314629
309452
311497
319206
309648
312319
307363
311277
308929
314897
302750
309027
300677
301399
299797
299005
292658
299124
294567
287763
292286
294021
289003
295719
288855
290985
298778
289779
297388
291428
286331
291996
287148
284909
289520
287486
292627
280084
284982
285968
288753
289375
280931
284499
285084
288820
284229
286876
285661
287984
282917
289575
294726
284166
282122
286860
291898
289604
288536
280131
286058
286202
287031
283337
283829
285652
280472
288785
279369
283904
282761
287954
285972
291750
284965
293330
285123
289740
283251
283587
284494
290812
284384
285296
284077
284702
280494
281710
285913
291456
287577
284970
290912
287222
285913
287543
286596
282751
289024
288139
286224
290381
293021
286817
290090
289713
280822
279434
287362
277042
284329
285357
286829
289169
288219
283052
285965
288747
296898
290349
288481
291133
293596
294659
282075
293718
286625
288560
289029
286798
287142
287911
281177
282737
279430
281454
286127
288594
284101
280943
276548
289578
282075
289027
285320
289151
283776
283056
285664
284449
282851
283866
285099
289578
286889
281972
283125
287694
288923
289231
290555
285388
293463
295968
293608
300004
295486
290794
291294
291879
290063
286693
285569
286050
286323
281936
287625
276431
286076
284340
283431
286037
286545
289934
295879
317203
322896
333166
332363
340069
345770
330573
305247
300735
289538
284492
285626
293037
292726
284471
288823
285852
289386
293275
293086
285263
291854
293470
293342
289261
293755
297674
291775
292233
290491
293781
293425
291698
301533
304225
304283
303099
294523
298879
305891
307921
297756
301802
308532
305478
306899
307412
310901
305989
299675
304784
309154
300849
312485
308083
308008
302882
308996
312040
306407
315384
312917
317729
311746
317740
316257
316165
316906
331781
322533
321423
319402
332910
316682
318820
317733
325350
320998
319638
325892
323317
328833
320004
330328
329430
331298
331315
334562
334431
333748
336930
344246
339108
343216
348333
347807
346095
348757
344229
346464
360173
355667
354266
349900
353799
355818
343675
350520
354145
356322
356106
354753
358778
349627
358309
361579
356985
359470
364149
362682
373399
373464
383029
377690
376665
382102
379451
385276
387376
382881
382456
394051
389426
385101
396548
391752
393634
398824
386888
390718
396927
394960
391617
398866
380548
385504
378439
377730
378504
378743
373023
371418
374179
369983
368645
368826
367893
365019
364101
372160
367069
364531
371383
366402
368088
370551
376817
368507
374848
374501
373571
377920
373679
379753
378640
370976
371397
373123
381505
384888
378167
387040
382395
375501
384446
374759
379536
379664
378567
386025
382822
386616
400657
390947
395739
401881
402002
393430
402108
403029
397744
401724
401306
400604
394262
386740
393700
389594
393044
382998
381459
374790
390769
393420
382674
379479
384735
381003
377744
384484
384362
385813
387157
386241
400223
409964
410585
401023
429732
461228
535535
645387
807495
1.05175e+006
1.29127e+006
1.21247e+006
791962
490060
400606
383268
381282
387172
382611
378595
391184
388288
382795
379594
388753
383520
386329
390482
386826
401452
385169
390366
393907
386883
391403
392273
393060
393838
388405
396161
393514
405387
400749
405754
405780
404114
402637
408926
400564
408003
417844
409788
424800
417145
417634
421722
425835
409632
428887
422773
421330
418774
424559
416672
415417
413043
406223
418018
422425
418634
420762
419557
429036
425600
418767
430023
429267
430840
426339
431439
438722
435925
436268
436681
438648
440082
436101
437044
439086
439073
439502
435515
435693
441027
448490
443434
439419
439882
439174
448570
444972
444220
451355
453985
462534
455719
456422
452286
468653
464683
460554
468148
465717
468012
465390
472929
488749
474576
476484
487633
508624
516393
534489
529190
510605
509034
495593
486139
479964
490916
471763
476894
478451
474914
478655
465552
472749
474909
477996
477347
472153
484621
480768
477357
473219
487071
483214
483252
483043
480900
480651
479152
489239
479835
482474
483601
483475
493169
486384
493466
491469
491398
507726
496298
500605
494241
502714
487584
504292
482153
505561
503773
492210
496662
498551
495517
497122
488578
498980
495686
494817
500878
498801
507633
509493
509901
509793
518010
510644
508614
515300
517035
510968
505192
509073
510066
518689
508771
524582
516686
522580
527287
536724
539093
534250
540321
534764
548075
551686
557245
556325
548934
552680
560830
556562
572451
568548
571871
564371
572733
570124
573817
574167
575527
581042
575871
575828
583076
578670
583186
584159
590603
583363
579417
585217
580987
583366
572866
584716
575614
593828
585309
588877
605096
602861
616810
640399
679850
696824
715491
687024
650649
627576
630935
618053
654862
662492
725815
796432
858291
935081
909742
792444
712646
662012
618504
608261
587633
589310
598416
597545
605768
579528
579941
556520
523705
529293
510439
539687
514730
478259
447229
433905
428108
426960
418959
408695
407074
403823
411248
432798
450983
480495
552672
796405
1.82658e+006
1.89106e+006
759701
478120
443762
407109
401107
402792
430782
921177
2.46053e+006
1.69751e+006
475408
296441
266117
274858
298105
334405
335687
314184
293894
271553
264816
248505
237008
223336
213138
206994
203664
208267
204843
201645
205402
205154
206584
207884
204364
203390
202185
206104
207304
209358
207964
211244
208747
212501
213587
216072
223588
225911
228271
234408
232890
225114
224624
218827
220223
213842
213736
218251
210042
215431
215240
208250
211164
209322
213183
206798
209391
208520
212565
213293
216422
214006
214979
244717
289259
355145
373344
366148
328812
287980
245124
221033
274584
399325
462617
301818
201151
200133
194529
190741
192981
192456
189908
193378
204654
202573
204236
211720
209221
211631
219028
221340
228482
233573
239741
243070
242137
243683
227915
227176
220254
219063
216197
209587
210049
208703
207713
201942
204236
202286
192483
195527
195420
190603
192249
190760
187562
192846
193245
195535
192244
198147
202221
200888
196408
199106
199039
197019
202819
206424
202638
200823
204533
203623
205054
193253
192759
180319
172113
168693
161863
153063
155132
155473
154679
158376
160539
166321
159328
155337
156343
152538
146326
138138
132442
132405
127968
126946
127942
129960
141561
170785
226543
489315
1.09664e+006
1.56843e+006
1.62233e+006
855681
190861
76701.8
63331.3
64045.1
60995.6
60798.5
55752.8
58492.5
53348.1
54720.8
51730.5
54049.2
49772.2
48593.8
52379.5
48931.7
47087.4
46032.9
49218.9
46421.5
48132
51784
52807.5
52800.5
53137
51723.5
46876.2
48382.6
47011.3
48315
47923.6
48965.5
51109.6
55293.8
62519
92754.2
207377
213094
199742
313621
155850
48950
34632
32068.3
29993.1
31382.7
31900.8
31606.5
32171.1
33800
34282.9
39087.9
39677.8
42349.9
42034.6
44302.6
38586.7
35875.2
31306.6
30133.9
29337
34306.8
60588.8
79818.8
42074
29466.6
33973.1
74663.2
119936
60394.5
26486.1
23521.2
22275.2
22482.2
23191.7
24116.7
24764.3
27564.5
28551.5
27816.5
24596.8
21886.6
21308
19869.2
20860.3
21261.5
23088.9
25075.4
24365.9
21955.6
20450.6
17295.6
16339.7
19139.9
21316.4
24388.4
25551.3
27436.4
30743.5
35966.7
38334.7
36645.3
33532.5
24161.7
9301.75
3108.56
2237.09
2203.3
1824.59
1833.04
2253.99
1
Valence - 590eV
PbSe-GeS Annealed
2011
4
10
7
41
2
0
7
Casa Info Follows
0
0
0
0

Lens Mode = Transmission
XPS
1

590
1e+037
1e+037
1e+037
1e+037
1e+037
FAT
100
1e+037
1e+037
1e+037
1e+037
1e+037
1e+037
1e+037
Valence - 590eV

-1
Kinetic Energy
eV
560
0.1
2
Intensity
d
Transmission
d
pulse counting
400
2
1e+037
1e+037
1e+037
1e+037
0
702
0
1
0
1
236058
1
172498
1
136675
1
110628
1
92450.1
1
85178.5
1
74256.3
1
75889.4
1
72686.5
1
71085.8
1
70816.9
1
64868.7
1
66814.3
1
64062
1
64668.8
1
61592.6
1
61981.1
1
61416.6
1
62761.1
1
63649.5
1
62934.3
1
63435.5
1
61675.6
1
63583.3
1
61053.4
1
60273.4
1
61519.4
1
64309.8
1
60860.5
1
62734.4
1
59521.6
1
60115.7
1
60888.6
1
61427.9
1
60726.7
1
64563.2
1
61067.4
1
63939.5
1
61699.6
1
64681.4
1
65620.5
1
65147.4
1
66135.7
1
63887.4
1
66254
1
67508.4
1
68419.3
1
69379.5
1
69038.8
1
69924.3
1
71968.5
1
70825.3
1
73496.1
1
75650.1
1
76469.5
1
74546.3
1
76953.8
1
76845.4
1
78560.1
1
77977.3
1
79093.7
1
80923.9
1
84626.6
1
83006.2
1
82141.7
1
83565.1
1
85803.6
1
85309.4
1
87035.5
1
86304.8
1
83759.4
1
81995.3
1
87311.4
1
86880.6
1
84819.5
1
84315.5
1
83123
1
82751.3
1
83189.2
1
78726.3
1
74076.1
1
79112
1
76430
1
72144.5
1
72723.1
1
69586.4
1
70605.7
1
65545.9
1
64644.8
1
66313.1
1
61035.1
1
61026.6
1
60456.4
1
60659.2
1
62189.5
1
59528.7
1
60670.4
1
59575.1
1
61558.8
1
60127
1
60925.3
1
61308.2
1
62751.2
1
63467.8
1
66499
1
69793.4
1
80987.3
1
88955.8
1
106033
1
123403
1
147517
1
159680
1
172594
1
172953
1
167288
1
155410
1
137514
1
117634
1
99245.9
1
84385.9
1
75748.6
1
66435.6
1
63051.1
1
57625.2
1
59313.2
1
56807.3
1
60238.2
1
60452.2
1
62176.8
1
63542.5
1
68253.2
1
77963.2
1
96413.2
1
112236
1
139371
1
179491
1
211372
1
244418
1
266248
1
268106
1
257325
1
228566
1
196146
1
159523
1
122718
1
101238
1
81360.4
1
66172.4
1
54912.3
1
54243.5
1
50349.4
1
50059.4
1
51833.3
1
46715.7
1
45803.4
1
45711.9
1
47281.7
1
45438.8
1
45405
1
45717.5
1
45444.4
1
45811.8
1
47506.9
1
49110.5
1
47287.3
1
47619.5
1
45649.9
1
46065.3
1
47316.9
1
48092.6
1
46377.8
1
46715.7
1
48212.3
1
48274.2
1
48022.2
1
50418.4
1
49979.1
1
50680.2
1
51592.5
1
51682.6
1
48614.9
1
53273.5
1
53849.3
1
53888.8
1
56651
1
55552.8
1
56170.9
1
56591.8
1
56317.3
1
54749
1
56789
1
54351.9
1
56969.2
1
57380.3
1
56955.1
1
54767.3
1
54170.3
1
51712.2
1
51182.8
1
51142
1
50457.8
1
49351.2
1
48799.3
1
47022.6
1
46328.5
1
47028.2
1
44405.4
1
47663.2
1
43690.2
1
43624
1
43705.7
1
40176.2
1
41933.2
1
40854.8
1
40960.4
1
41861.4
1
43762
1
40431
1
42734.3
1
43115.8
1
41174.3
1
42081
1
43998.5
1
45690.8
1
46128.6
1
47235.2
1
46705.8
1
47453.4
1
46915.6
1
48524.8
1
48230.6
1
51088.5
1
48188.3
1
50471.9
1
49562.4
1
50367.7
1
51309.5
1
51127.9
1
49770.8
1
48272.8
1
45654.2
1
48700.8
1
50471.9
1
44177.3
1
46203.2
1
46845.2
1
46193.4
1
43222.8
1
43324.2
1
41767.1
1
41444.7
1
41039.2
1
38212.2
1
38720.4
1
36745.2
1
37991.2
1
36182.1
1
36636.8
1
33471.9
1
35290.9
1
35631.6
1
36801.5
1
36291.9
1
36037.1
1
36239.8
1
37972.9
1
38534.6
1
38603.6
1
39782
1
41571.4
1
44228
1
43846.5
1
49901.7
1
47847.6
1
49175.2
1
50591.5
1
53543.8
1
54014.1
1
55329
1
55030.5
1
54756
1
55906.2
1
59075.3
1
57971.6
1
59352.7
1
61693.9
1
64401.3
1
64381.6
1
65989.3
1
66427.2
1
65689.5
1
70335.4
1
67911.1
1
71406.8
1
69592.1
1
72037.5
1
71799.6
1
73273.6
1
74985.6
1
77298.7
1
77773.1
1
79841.3
1
78822
1
78515.1
1
75868.3
1
73617.1
1
70894.3
1
71350.5
1
67190.2
1
62685.1
1
62683.7
1
58996.5
1
53496
1
53490.3
1
50259.3
1
41410.9
1
38820.4
1
30988.5
1
25235.9
1
18688
1
13601.4
1
11068.6
1
7616.54
1
6761.96
1
5195.01
1
4874.02
1
4823.34
1
4382.68
1
4315.1
1
3988.47
1
3988.47
1
4275.68
1
3563.3
1
4384.08
1
4623.42
1
3601.31
1
4016.63
1
3789.97
1
4032.12
1
4244.71
1
4786.73
1
4360.15
1
3816.72
1
4161.64
1
4306.65
1
3150.8
1
3490.09
1
3761.81
1
3961.73
1
3597.09
1
3646.36
1
Se3d - 590eV
PbSe-GeS Annealed
2011
4
10
7
41
2
0
7
Casa Info Follows
0
0
0
0

Lens Mode = Transmission
XPS
1

590
1e+037
1e+037
1e+037
1e+037
1e+037
FAT
100
1e+037
1e+037
1e+037
1e+037
1e+037
1e+037
1e+037
Se3d - 590eV

-1
Kinetic Energy
eV
531
0.1
2
Intensity
d
Transmission
d
pulse counting
400
2
1e+037
1e+037
1e+037
1e+037
0
282
0
1
0
1
326023
1
318561
1
318198
1
321277
1
322861
1
313511
1
304035
1
304584
1
313960
1
300607
1
296188
1
293941
1
295251
1
287968
1
290441
1
293051
1
289862
1
292552
1
287397
1
286477
1
283359
1
279227
1
273818
1
280553
1
268990
1
274337
1
277007
1
272958
1
283249
1
275629
1
265978
1
270245
1
270776
1
271716
1
271292
1
270222
1
268348
1
273101
1
271712
1
274329
1
264254
1
272952
1
273256
1
270999
1
266927
1
273869
1
279810
1
281511
1
287956
1
304245
1
303731
1
315115
1
331340
1
349757
1
351317
1
371687
1
381735
1
403583
1
424020
1
464854
1
505884
1
577428
1
671139
1
809634
1
964127
1
1.15924e+006
1
1.38164e+006
1
1.66121e+006
1
1.95298e+006
1
2.24919e+006
1
2.55622e+006
1
2.80256e+006
1
3.03812e+006
1
3.16661e+006
1
3.32658e+006
1
3.46731e+006
1
3.53485e+006
1
3.6334e+006
1
3.61667e+006
1
3.55774e+006
1
3.39425e+006
1
3.14359e+006
1
2.73879e+006
1
2.28586e+006
1
1.82604e+006
1
1.39419e+006
1
1.00802e+006
1
717678
1
498851
1
358212
1
271152
1
214296
1
185341
1
169873
1
160568
1
154019
1
146219
1
146644
1
139535
1
145296
1
142894
1
138743
1
133705
1
132968
1
136149
1
130724
1
131459
1
135711
1
132425
1
130700
1
127866
1
122835
1
124792
1
124475
1
125864
1
124313
1
120485
1
123172
1
123484
1
122015
1
124922
1
124689
1
121548
1
119939
1
115980
1
117143
1
121943
1
117593
1
118020
1
115716
1
116194
1
112926
1
113905
1
113609
1
112045
1
111258
1
110759
1
112059
1
112726
1
107904
1
107283
1
Pb4f - 590eV
PbSe-GeS Annealed
2011
4
10
7
41
2
0
7
Casa Info Follows
0
0
0
0

Lens Mode = Transmission
XPS
1

590
1e+037
1e+037
1e+037
1e+037
1e+037
FAT
100
1e+037
1e+037
1e+037
1e+037
1e+037
1e+037
1e+037
Pb4f - 590eV

-1
Kinetic Energy
eV
440
0.1
2
Intensity
d
Transmission
d
pulse counting
400
2
1e+037
1e+037
1e+037
1e+037
0
402
0
1
0
1
1.09145e+006
1
1.08127e+006
1
1.08267e+006
1
1.08253e+006
1
1.08118e+006
1
1.06643e+006
1
1.0682e+006
1
1.0686e+006
1
1.07297e+006
1
1.07232e+006
1
1.08104e+006
1
1.10046e+006
1
1.09467e+006
1
1.10797e+006
1
1.11034e+006
1
1.10582e+006
1
1.09611e+006
1
1.11158e+006
1
1.10036e+006
1
1.0838e+006
1
1.05651e+006
1
1.02986e+006
1
1.01305e+006
1
1.0125e+006
1
997013
1
981536
1
954113
1
950461
1
947560
1
935764
1
930140
1
922257
1
916551
1
926930
1
907804
1
905999
1
892032
1
897519
1
888646
1
894818
1
895261
1
886801
1
891070
1
871723
1
882403
1
866047
1
866165
1
874342
1
869832
1
858838
1
859699
1
867428
1
852528
1
853463
1
854725
1
843880
1
850959
1
840167
1
838554
1
843932
1
839569
1
837283
1
846376
1
847998
1
830629
1
849034
1
835447
1
847004
1
850547
1
847135
1
856931
1
873421
1
856562
1
869800
1
873397
1
867511
1
863986
1
890514
1
905456
1
922546
1
930234
1
943885
1
949523
1
974152
1
990533
1
1.01054e+006
1
1.03476e+006
1
1.06095e+006
1
1.09837e+006
1
1.13153e+006
1
1.1713e+006
1
1.22181e+006
1
1.28114e+006
1
1.39107e+006
1
1.55726e+006
1
1.81852e+006
1
2.18811e+006
1
2.68449e+006
1
3.27366e+006
1
3.86813e+006
1
4.41537e+006
1
4.78871e+006
1
4.78077e+006
1
4.53255e+006
1
4.04919e+006
1
3.40546e+006
1
2.77502e+006
1
2.19446e+006
1
1.77169e+006
1
1.4651e+006
1
1.26407e+006
1
1.14065e+006
1
1.06368e+006
1
1.01169e+006
1
968205
1
942820
1
930873
1
915453
1
909899
1
896761
1
886637
1
873565
1
859749
1
861670
1
850585
1
842416
1
837875
1
832066
1
834228
1
827322
1
822625
1
811733
1
829911
1
817799
1
830661
1
817805
1
824906
1
834236
1
849399
1
877887
1
933989
1
1.00754e+006
1
1.16851e+006
1
1.41278e+006
1
1.81396e+006
1
2.39637e+006
1
3.11481e+006
1
4.02957e+006
1
4.94101e+006
1
5.62707e+006
1
5.96709e+006
1
5.86349e+006
1
5.28539e+006
1
4.43144e+006
1
3.46911e+006
1
2.63352e+006
1
1.91728e+006
1
1.413e+006
1
1.08024e+006
1
886511
1
758154
1
694780
1
654159
1
626019
1
601461
1
582574
1
571892
1
571910
1
562466
1
560902
1
564473
1
558560
1
562058
1
570618
1
572940
1
578837
1
578482
1
594937
1
608087
1
623699
1
632212
1
653282
1
671397
1
684753
1
684066
1
710971
1
709789
1
713540
1
706798
1
703799
1
699971
1
695455
1
677173
1
669907
1
643735
1
644870
1
636520
1
625101
1
599952
1
608205
1
587388
1
C1s - 590eV
PbSe-GeS Annealed
2011
4
10
7
41
2
0
7
Casa Info Follows
0
0
0
0

Lens Mode = Transmission
XPS
1

590
1e+037
1e+037
1e+037
1e+037
1e+037
FAT
100
1e+037
1e+037
1e+037
1e+037
1e+037
1e+037
1e+037
C1s - 590eV

-1
Kinetic Energy
eV
298
0.1
2
Intensity
d
Transmission
d
pulse counting
400
2
1e+037
1e+037
1e+037
1e+037
0
242
0
1
0
1
766487
1
771369
1
763753
1
775653
1
763115
1
772573
1
760323
1
767892
1
767671
1
770109
1
761136
1
759488
1
763598
1
773042
1
772701
1
772443
1
774651
1
778506
1
774745
1
769945
1
775860
1
771828
1
768131
1
772839
1
788074
1
774109
1
779374
1
782173
1
775556
1
773819
1
773858
1
781243
1
781626
1
783933
1
768189
1
776943
1
773036
1
787924
1
782063
1
782472
1
792807
1
780030
1
786887
1
785925
1
792791
1
794647
1
791144
1
797487
1
800232
1
812882
1
807862
1
813563
1
825333
1
820111
1
817499
1
819304
1
815839
1
815814
1
814184
1
825900
1
824230
1
831644
1
836983
1
829203
1
843681
1
851340
1
865674
1
867680
1
889754
1
913016
1
919954
1
949325
1
973426
1
1.01455e+006
1
1.04697e+006
1
1.08219e+006
1
1.12257e+006
1
1.18719e+006
1
1.21403e+006
1
1.3016e+006
1
1.33541e+006
1
1.39986e+006
1
1.4924e+006
1
1.54577e+006
1
1.62928e+006
1
1.75415e+006
1
1.84779e+006
1
1.96377e+006
1
2.09073e+006
1
2.22373e+006
1
2.36819e+006
1
2.51149e+006
1
2.62728e+006
1
2.74886e+006
1
2.82062e+006
1
2.82086e+006
1
2.84588e+006
1
2.80402e+006
1
2.70874e+006
1
2.56706e+006
1
2.38556e+006
1
2.20614e+006
1
1.97657e+006
1
1.77293e+006
1
1.5758e+006
1
1.4007e+006
1
1.25677e+006
1
1.12201e+006
1
1.02449e+006
1
952402
1
904134
1
868967
1
831941
1
806215
1
799377
1
786759
1
793338
1
781990
1
787267
1
770989
1
774409
1
Pb4d - 590eV
PbSe-GeS Annealed
2011
4
10
7
41
2
0
7
Casa Info Follows
0
0
0
0

Lens Mode = Transmission
XPS
1

590
1e+037
1e+037
1e+037
1e+037
1e+037
FAT
100
1e+037
1e+037
1e+037
1e+037
1e+037
1e+037
1e+037
Pb4d - 590eV

-1
Kinetic Energy
eV
146
0.1
2
Intensity
d
Transmission
d
pulse counting
400
2
1e+037
1e+037
1e+037
1e+037
0
842
0
1
0
1
576476
1
572747
1
569227
1
576586
1
577226
1
587936
1
576530
1
570400
1
567407
1
573100
1
577122
1
568119
1
581214
1
577321
1
570811
1
579402
1
571979
1
570291
1
583948
1
566783
1
579067
1
575796
1
583983
1
575078
1
573973
1
580227
1
577039
1
580791
1
575771
1
583721
1
572872
1
572120
1
580120
1
580610
1
579984
1
575279
1
573853
1
570753
1
580628
1
575461
1
573266
1
571816
1
579462
1
573897
1
577763
1
572161
1
571681
1
579941
1
576758
1
573217
1
581696
1
587922
1
572114
1
578389
1
571653
1
579686
1
588409
1
581632
1
581651
1
576884
1
576679
1
576093
1
575724
1
577546
1
574033
1
580936
1
585820
1
582047
1
573788
1
580859
1
578009
1
572920
1
562324
1
571813
1
570317
1
577780
1
571665
1
570439
1
568289
1
571505
1
574750
1
574009
1
574437
1
572856
1
565789
1
575354
1
575689
1
577821
1
582902
1
565533
1
580729
1
574801
1
574390
1
577394
1
569808
1
574628
1
581637
1
565345
1
567811
1
572744
1
579099
1
575129
1
574433
1
574919
1
571484
1
579716
1
578485
1
576562
1
580450
1
572811
1
574934
1
579076
1
586278
1
589901
1
571561
1
580405
1
577767
1
579907
1
584750
1
578156
1
580251
1
579942
1
581978
1
575174
1
577312
1
576624
1
590698
1
583704
1
570673
1
569089
1
574995
1
572738
1
578196
1
573049
1
586644
1
573101
1
576175
1
574570
1
578912
1
576606
1
580597
1
570017
1
573066
1
574204
1
570236
1
577712
1
581995
1
569496
1
569376
1
565949
1
569000
1
580252
1
570721
1
571775
1
581240
1
565844
1
570283
1
577211
1
570502
1
575740
1
569846
1
565485
1
572482
1
575139
1
574364
1
573915
1
563149
1
568268
1
570683
1
568705
1
569373
1
575468
1
574898
1
574764
1
560566
1
574956
1
572075
1
581209
1
565305
1
573746
1
565223
1
573321
1
577671
1
567057
1
575609
1
577488
1
561078
1
566187
1
568750
1
572890
1
573781
1
575743
1
568432
1
568112
1
573543
1
574036
1
572445
1
575099
1
578318
1
574522
1
578792
1
569844
1
567519
1
570428
1
572540
1
578753
1
570921
1
566449
1
574585
1
567882
1
570564
1
577760
1
571930
1
570082
1
581874
1
578888
1
584753
1
577581
1
574093
1
574283
1
579406
1
573023
1
576580
1
570528
1
576024
1
576407
1
575450
1
579204
1
573625
1
576296
1
573054
1
573596
1
575462
1
590862
1
573991
1
579542
1
580784
1
577867
1
584750
1
570640
1
579128
1
575807
1
582119
1
578686
1
582023
1
578875
1
581878
1
571111
1
583903
1
575295
1
592640
1
578967
1
581894
1
578458
1
579613
1
578211
1
585284
1
583270
1
581585
1
579499
1
579071
1
578774
1
578679
1
587177
1
589645
1
595081
1
588622
1
579913
1
572941
1
575522
1
584547
1
579835
1
585223
1
583521
1
594284
1
584847
1
594592
1
587583
1
587404
1
587959
1
595836
1
583177
1
590683
1
594885
1
582834
1
584026
1
581049
1
588854
1
586434
1
575733
1
587783
1
588868
1
588913
1
594302
1
584073
1
588401
1
583869
1
588695
1
581243
1
585196
1
591739
1
583957
1
582699
1
591378
1
581222
1
592060
1
588548
1
593817
1
585194
1
591473
1
592061
1
589388
1
583213
1
585264
1
594126
1
587101
1
584159
1
588512
1
596334
1
593766
1
588710
1
591123
1
593687
1
593646
1
595841
1
605471
1
598708
1
607694
1
598944
1
609309
1
597660
1
600745
1
609882
1
609027
1
610739
1
613256
1
611035
1
603059
1
613776
1
616159
1
602696
1
607289
1
598442
1
602645
1
608340
1
605948
1
604070
1
606820
1
604086
1
606445
1
603472
1
597901
1
601214
1
600852
1
600565
1
591689
1
604763
1
596984
1
599600
1
594615
1
598053
1
594714
1
591053
1
589786
1
595505
1
594975
1
596780
1
584452
1
594311
1
595332
1
593300
1
594012
1
591016
1
587536
1
594056
1
594332
1
587776
1
583261
1
587027
1
587890
1
592688
1
580732
1
577466
1
580167
1
592475
1
592175
1
588413
1
583914
1
591485
1
582174
1
582175
1
586760
1
578460
1
577663
1
582899
1
587799
1
584622
1
581725
1
582975
1
578730
1
589098
1
580850
1
588868
1
579326
1
591083
1
577205
1
587281
1
579027
1
588153
1
580473
1
571822
1
583287
1
585760
1
593991
1
594697
1
582842
1
583738
1
586615
1
589779
1
586463
1
575858
1
Pb5d - 590eV
PbSe-GeS Annealed
2011
4
10
7
41
2
0
7
Casa Info Follows
0
0
0
0

Lens Mode = Transmission
XPS
1

590
1e+037
1e+037
1e+037
1e+037
1e+037
FAT
100
1e+037
1e+037
1e+037
1e+037
1e+037
1e+037
1e+037
Pb5d - 590eV

-1
Kinetic Energy
eV
565
0.05
2
Intensity
d
Transmission
d
pulse counting
400
2
1e+037
1e+037
1e+037
1e+037
0
442
0
1
0
1
70722.6
1
70938
1
72999.1
1
73269.4
1
72454.2
1
75581.1
1
74811
1
75993.6
1
77336.7
1
74202.8
1
75902.1
1
80591.7
1
76735.5
1
78875.5
1
82003.8
1
75734.6
1
81184.4
1
79594.9
1
80759.2
1
80891.6
1
80688.8
1
83293.4
1
81077.4
1
80511.4
1
80398.8
1
81305.5
1
81498.3
1
83711.5
1
82368.4
1
83130.1
1
83261
1
84891.3
1
84438
1
85864.1
1
85360.1
1
84923.7
1
85443.2
1
84278.9
1
86501.9
1
89817.4
1
87007.3
1
87024.2
1
86648.3
1
86010.5
1
83842.4
1
85198.2
1
86296.3
1
88834.7
1
84781.5
1
83904.4
1
82243.1
1
83435.6
1
82207.9
1
83244.1
1
81508.2
1
81353.3
1
80135.5
1
81114
1
78272.9
1
77332.5
1
77415.5
1
77652.1
1
75619.1
1
75565.6
1
74767.4
1
71982.6
1
72117.8
1
71166
1
69979.2
1
68906.4
1
72223.3
1
71275.9
1
70332.6
1
66969.2
1
67309.9
1
63590.3
1
66479.3
1
65627.5
1
62997.6
1
64451.9
1
63134.2
1
62020.6
1
63648.1
1
59472.3
1
60094.6
1
58392.5
1
60923.8
1
58886.7
1
60115.7
1
61191.3
1
58261.6
1
59808.8
1
58858.5
1
58912
1
58468.5
1
59268.2
1
59306.2
1
59342.8
1
60310
1
58845.8
1
59120.4
1
58379.8
1
59044.3
1
59686.3
1
60356.5
1
61197
1
61633.4
1
66200.5
1
66068.2
1
71903.8
1
72267
1
79656.9
1
82129.1
1
92312.1
1
99687.9
1
105435
1
117167
1
122395
1
137034
1
145313
1
155241
1
161442
1
172176
1
173765
1
176591
1
180139
1
176138
1
168210
1
166694
1
156366
1
151889
1
137372
1
128943
1
116950
1
106250
1
99683.7
1
90946.5
1
82813.3
1
77003
1
73750.9
1
66708.7
1
64943.3
1
62987.8
1
62665.4
1
63369.3
1
61853
1
59496.3
1
60563.4
1
57708.3
1
58816.3
1
59655.4
1
58175.7
1
58636.1
1
63618.5
1
62359.9
1
64012.7
1
63310.2
1
63938.1
1
66746.8
1
69114.8
1
73969.1
1
77355
1
84644.9
1
94511.2
1
103334
1
117488
1
127192
1
143777
1
161963
1
177574
1
199260
1
209631
1
231533
1
246256
1
263970
1
266608
1
266994
1
274453
1
270722
1
258617
1
249790
1
237312
1
218245
1
198606
1
180049
1
162229
1
143741
1
126834
1
108427
1
100444
1
88782.6
1
80132.7
1
73466.5
1
68310.9
1
61541.9
1
59466.7
1
57636.5
1
55593.7
1
51979.7
1
52485.1
1
52335.9
1
49507.5
1
46834
1
48119.3
1
50783
1
49539.9
1
48879.6
1
45793.5
1
48079.9
1
47447.8
1
47950.4
1
45606.3
1
47447.8
1
47357.7
1
47290.1
1
47839.2
1
47178.9
1
45828.7
1
46383.4
1
45231.8
1
46879
1
O1s - 590eV
PbSe-GeS Annealed
2011
4
10
7
41
2
0
7
Casa Info Follows
0
0
0
0

Lens Mode = Transmission
XPS
1

590
1e+037
1e+037
1e+037
1e+037
1e+037
FAT
100
1e+037
1e+037
1e+037
1e+037
1e+037
1e+037
1e+037
O1s - 590eV

-1
Kinetic Energy
eV
50
0.1
2
Intensity
d
Transmission
d
pulse counting
400
2
1e+037
1e+037
1e+037
1e+037
0
302
0
1
0
1
1.43258e+006
1
1.43921e+006
1
1.43444e+006
1
1.42693e+006
1
1.42043e+006
1
1.43427e+006
1
1.40687e+006
1
1.40915e+006
1
1.40399e+006
1
1.40111e+006
1
1.41399e+006
1
1.40223e+006
1
1.37607e+006
1
1.39134e+006
1
1.40505e+006
1
1.38437e+006
1
1.37356e+006
1
1.38189e+006
1
1.39261e+006
1
1.39074e+006
1
1.39987e+006
1
1.39294e+006
1
1.41595e+006
1
1.39985e+006
1
1.39536e+006
1
1.40637e+006
1
1.41087e+006
1
1.4303e+006
1
1.42739e+006
1
1.43704e+006
1
1.47445e+006
1
1.51509e+006
1
1.58565e+006
1
1.66478e+006
1
1.76638e+006
1
1.85202e+006
1
1.95899e+006
1
2.04429e+006
1
2.06526e+006
1
2.05659e+006
1
1.99658e+006
1
1.90178e+006
1
1.78148e+006
1
1.66716e+006
1
1.56872e+006
1
1.49464e+006
1
1.42661e+006
1
1.3814e+006
1
1.34212e+006
1
1.30693e+006
1
1.29722e+006
1
1.28799e+006
1
1.2649e+006
1
1.24737e+006
1
1.25371e+006
1
1.25389e+006
1
1.24003e+006
1
1.21784e+006
1
1.22347e+006
1
1.24409e+006
1
1.24956e+006
1
1.22761e+006
1
1.19634e+006
1
1.20623e+006
1
1.19968e+006
1
1.19909e+006
1
1.19521e+006
1
1.20784e+006
1
1.20815e+006
1
1.1882e+006
1
1.20913e+006
1
1.20042e+006
1
1.19178e+006
1
1.21131e+006
1
1.20564e+006
1
1.22976e+006
1
1.23069e+006
1
1.2498e+006
1
1.27127e+006
1
1.30656e+006
1
1.32389e+006
1
1.38292e+006
1
1.43329e+006
1
1.48283e+006
1
1.54186e+006
1
1.63267e+006
1
1.70115e+006
1
1.81747e+006
1
1.86668e+006
1
1.96614e+006
1
2.07123e+006
1
2.15949e+006
1
2.25567e+006
1
2.30139e+006
1
2.32646e+006
1
2.35331e+006
1
2.32839e+006
1
2.30361e+006
1
2.25915e+006
1
2.19239e+006
1
2.11703e+006
1
1.99759e+006
1
1.89089e+006
1
1.81504e+006
1
1.70696e+006
1
1.61992e+006
1
1.54617e+006
1
1.49318e+006
1
1.43358e+006
1
1.3732e+006
1
1.34999e+006
1
1.32056e+006
1
1.29729e+006
1
1.26706e+006
1
1.26006e+006
1
1.24307e+006
1
1.21938e+006
1
1.23305e+006
1
1.21284e+006
1
1.21661e+006
1
1.20281e+006
1
1.19901e+006
1
1.23012e+006
1
1.24246e+006
1
1.29671e+006
1
1.36703e+006
1
1.44185e+006
1
1.55246e+006
1
1.69107e+006
1
1.84532e+006
1
1.95329e+006
1
2.05667e+006
1
2.08416e+006
1
2.04733e+006
1
1.95633e+006
1
1.82668e+006
1
1.68998e+006
1
1.53199e+006
1
1.39853e+006
1
1.26345e+006
1
1.20391e+006
1
1.1509e+006
1
1.08752e+006
1
1.05568e+006
1
1.0399e+006
1
1.02411e+006
1
1.01254e+006
1
1.00583e+006
1
983697
1
983192
1
977314
1
S2s - 590eV
PbSe-GeS Annealed
2011
4
10
7
41
2
0
7
Casa Info Follows
0
0
0
0

Lens Mode = Transmission
XPS
1

590
1e+037
1e+037
1e+037
1e+037
1e+037
FAT
100
1e+037
1e+037
1e+037
1e+037
1e+037
1e+037
1e+037
S2s - 590eV

-1
Kinetic Energy
eV
345
0.1
2
Intensity
d
Transmission
d
pulse counting
400
1
1e+037
1e+037
1e+037
1e+037
0
602
0
1
0
1
443710
1
442132
1
439674
1
438677
1
440044
1
444713
1
437795
1
440992
1
436967
1
448579
1
439140
1
447576
1
443368
1
435664
1
446619
1
436343
1
448385
1
438831
1
446653
1
444828
1
437389
1
435974
1
442663
1
442342
1
442769
1
448152
1
450548
1
438873
1
445909
1
446630
1
444279
1
440676
1
443582
1
441416
1
440895
1
445712
1
447709
1
446502
1
446349
1
445158
1
445622
1
443975
1
439056
1
444413
1
443014
1
441520
1
444796
1
444324
1
439875
1
444119
1
448720
1
443057
1
449171
1
443944
1
443789
1
443575
1
452125
1
454382
1
453944
1
446371
1
441654
1
448614
1
446321
1
445341
1
451158
1
444496
1
445946
1
451058
1
442488
1
444952
1
453467
1
439401
1
442419
1
444216
1
450075
1
457041
1
453083
1
451376
1
453209
1
446511
1
445379
1
451632
1
453401
1
451563
1
454841
1
446443
1
451600
1
443560
1
445107
1
455490
1
454496
1
455798
1
452954
1
451120
1
443270
1
449466
1
453267
1
457562
1
454856
1
450858
1
466892
1
451745
1
449481
1
452773
1
454115
1
458120
1
450969
1
455784
1
455933
1
460613
1
459653
1
456053
1
462427
1
460163
1
460382
1
458151
1
467257
1
458164
1
465736
1
459153
1
456257
1
464578
1
458020
1
453137
1
451946
1
465843
1
456649
1
450629
1
460447
1
462878
1
473418
1
458604
1
462818
1
456544
1
468168
1
466667
1
464419
1
461899
1
458161
1
469711
1
470054
1
464008
1
466694
1
468178
1
468928
1
462679
1
477615
1
463901
1
471994
1
471925
1
469229
1
470177
1
468462
1
478946
1
472249
1
476090
1
475575
1
478675
1
476640
1
466706
1
473740
1
484736
1
484344
1
483996
1
478066
1
492339
1
492410
1
477874
1
492161
1
488922
1
498548
1
489170
1
493483
1
501633
1
497410
1
513474
1
511403
1
507664
1
517426
1
523839
1
513311
1
513984
1
537791
1
527197
1
538029
1
535728
1
537889
1
536270
1
532432
1
526539
1
521506
1
527668
1
520411
1
525724
1
520963
1
523346
1
508134
1
506519
1
505186
1
502696
1
507297
1
492705
1
492665
1
485154
1
494353
1
486170
1
490373
1
486260
1
483466
1
477099
1
483478
1
478330
1
478227
1
477474
1
479303
1
472588
1
473632
1
472503
1
478963
1
472086
1
473069
1
472275
1
467156
1
466623
1
471932
1
461321
1
461248
1
467906
1
465934
1
457696
1
465974
1
456004
1
458873
1
465149
1
463430
1
459913
1
462636
1
462325
1
465125
1
466744
1
468683
1
460843
1
461896
1
456307
1
464617
1
458873
1
462978
1
458408
1
462698
1
455075
1
461686
1
454151
1
462907
1
467395
1
462749
1
470149
1
458175
1
462743
1
469577
1
460693
1
472166
1
471904
1
465838
1
457277
1
470194
1
467415
1
466094
1
462022
1
466598
1
468066
1
468665
1
469331
1
465849
1
467543
1
467796
1
470703
1
466515
1
465491
1
468041
1
461005
1
475774
1
467181
1
476132
1
474547
1
480427
1
469673
1
465905
1
473808
1
468438
1
479241
1
473908
1
467465
1
472372
1
460039
1
475689
1
473169
1
475042
1
477165
1
473116
1
470551
1
476281
1
N1s - 590eV
PbSe-GeS Annealed
2011
4
10
7
41
2
0
7
Casa Info Follows
0
0
0
0

Lens Mode = Transmission
XPS
1

590
1e+037
1e+037
1e+037
1e+037
1e+037
FAT
100
1e+037
1e+037
1e+037
1e+037
1e+037
1e+037
1e+037
N1s - 590eV

-1
Kinetic Energy
eV
180
0.1
2
Intensity
d
Transmission
d
pulse counting
400
2
1e+037
1e+037
1e+037
1e+037
0
402
0
1
0
1
588667
1
590580
1
599889
1
597621
1
597548
1
590110
1
586492
1
588847
1
589457
1
588623
1
591423
1
591967
1
579330
1
583168
1
587225
1
584761
1
582461
1
576890
1
573106
1
586435
1
578885
1
582710
1
579442
1
580196
1
578061
1
567208
1
578120
1
573831
1
576541
1
576290
1
570861
1
573828
1
575754
1
569997
1
583116
1
573596
1
568332
1
575092
1
564077
1
575051
1
574388
1
575781
1
572343
1
575834
1
570943
1
580441
1
573880
1
581992
1
574688
1
572000
1
585388
1
564532
1
566701
1
569886
1
572721
1
571461
1
574854
1
567246
1
573686
1
574067
1
570671
1
566010
1
574157
1
571953
1
571888
1
573814
1
572076
1
571199
1
573721
1
572517
1
570845
1
565857
1
569069
1
569137
1
575934
1
566796
1
568967
1
571858
1
568308
1
575517
1
569296
1
567744
1
579159
1
578058
1
574177
1
572160
1
574582
1
566934
1
577455
1
574725
1
583613
1
579469
1
577407
1
581536
1
579150
1
589599
1
584777
1
584436
1
590667
1
593406
1
597074
1
608016
1
621380
1
621556
1
625423
1
628820
1
635592
1
636268
1
637438
1
645954
1
647311
1
625433
1
635046
1
640118
1
636773
1
637269
1
635934
1
641373
1
651387
1
648338
1
657872
1
649412
1
666001
1
672848
1
670637
1
679032
1
673985
1
681980
1
692260
1
687776
1
672720
1
674991
1
672236
1
670710
1
649008
1
652192
1
640365
1
627396
1
629841
1
621219
1
606609
1
595301
1
598381
1
597197
1
598774
1
594495
1
580552
1
588458
1
583380
1
586749
1
575782
1
582921
1
583873
1
586669
1
581584
1
584806
1
585220
1
595678
1
585130
1
588853
1
581723
1
578777
1
584978
1
581616
1
585872
1
585912
1
589994
1
585289
1
591281
1
583072
1
585362
1
590600
1
585005
1
578135
1
587708
1
584032
1
583729
1
581629
1
580728
1
584398
1
581428
1
579969
1
588594
1
583439
1
578463
1
586221
1
581874
1
582077
1
574080
1
579701
1
586147
1
577242
1
595727
1
585187
1
590687
1
583292
1
592972
1
583532
1
584895
1
583183
1
586010
1
S2p - 590eV
PbSe-GeS Annealed
2011
4
10
7
41
2
0
7
Casa Info Follows
0
0
0
0

Lens Mode = Transmission
XPS
1

590
1e+037
1e+037
1e+037
1e+037
1e+037
FAT
100
1e+037
1e+037
1e+037
1e+037
1e+037
1e+037
1e+037
S2p - 590eV

-1
Kinetic Energy
eV
412
0.1
2
Intensity
d
Transmission
d
pulse counting
400
3
1e+037
1e+037
1e+037
1e+037
0
602
0
1
0
1
1.68278e+006
1
1.6827e+006
1
1.68505e+006
1
1.69216e+006
1
1.69406e+006
1
1.67817e+006
1
1.68858e+006
1
1.70325e+006
1
1.68339e+006
1
1.68596e+006
1
1.68747e+006
1
1.67932e+006
1
1.70601e+006
1
1.6841e+006
1
1.68901e+006
1
1.68989e+006
1
1.68731e+006
1
1.69186e+006
1
1.68864e+006
1
1.70228e+006
1
1.69724e+006
1
1.69669e+006
1
1.70499e+006
1
1.7146e+006
1
1.69173e+006
1
1.68824e+006
1
1.7024e+006
1
1.69545e+006
1
1.71987e+006
1
1.7116e+006
1
1.7062e+006
1
1.70831e+006
1
1.6888e+006
1
1.69787e+006
1
1.69394e+006
1
1.71232e+006
1
1.70998e+006
1
1.69748e+006
1
1.70448e+006
1
1.72064e+006
1
1.71711e+006
1
1.71198e+006
1
1.70871e+006
1
1.70636e+006
1
1.72516e+006
1
1.7112e+006
1
1.70328e+006
1
1.70552e+006
1
1.70483e+006
1
1.71712e+006
1
1.70726e+006
1
1.70069e+006
1
1.70732e+006
1
1.69723e+006
1
1.70519e+006
1
1.69171e+006
1
1.69898e+006
1
1.71132e+006
1
1.69877e+006
1
1.69368e+006
1
1.71188e+006
1
1.69443e+006
1
1.701e+006
1
1.71209e+006
1
1.70792e+006
1
1.68864e+006
1
1.68932e+006
1
1.70246e+006
1
1.71249e+006
1
1.70499e+006
1
1.70566e+006
1
1.69764e+006
1
1.68047e+006
1
1.70317e+006
1
1.68574e+006
1
1.7082e+006
1
1.70866e+006
1
1.69651e+006
1
1.70457e+006
1
1.70336e+006
1
1.68399e+006
1
1.69036e+006
1
1.68877e+006
1
1.69639e+006
1
1.69858e+006
1
1.68994e+006
1
1.69177e+006
1
1.67896e+006
1
1.67623e+006
1
1.69796e+006
1
1.67482e+006
1
1.68549e+006
1
1.6941e+006
1
1.71214e+006
1
1.694e+006
1
1.72166e+006
1
1.69812e+006
1
1.69936e+006
1
1.71637e+006
1
1.71022e+006
1
1.69e+006
1
1.71546e+006
1
1.69283e+006
1
1.69192e+006
1
1.71975e+006
1
1.71556e+006
1
1.72323e+006
1
1.71147e+006
1
1.7272e+006
1
1.72378e+006
1
1.72482e+006
1
1.71635e+006
1
1.73271e+006
1
1.7466e+006
1
1.73708e+006
1
1.74133e+006
1
1.74963e+006
1
1.74858e+006
1
1.74559e+006
1
1.75503e+006
1
1.7773e+006
1
1.76996e+006
1
1.77431e+006
1
1.78776e+006
1
1.79702e+006
1
1.81689e+006
1
1.82384e+006
1
1.8215e+006
1
1.81433e+006
1
1.84332e+006
1
1.8501e+006
1
1.84679e+006
1
1.86275e+006
1
1.89056e+006
1
1.89091e+006
1
1.93601e+006
1
1.96247e+006
1
1.96023e+006
1
1.98014e+006
1
2.00045e+006
1
2.02061e+006
1
2.0239e+006
1
2.05876e+006
1
2.08269e+006
1
2.09458e+006
1
2.10939e+006
1
2.12544e+006
1
2.13906e+006
1
2.1459e+006
1
2.13204e+006
1
2.13249e+006
1
2.12875e+006
1
2.09712e+006
1
2.10398e+006
1
2.06362e+006
1
2.05327e+006
1
2.02143e+006
1
2.01657e+006
1
1.98588e+006
1
1.97134e+006
1
1.958e+006
1
1.94038e+006
1
1.92549e+006
1
1.89095e+006
1
1.88504e+006
1
1.89367e+006
1
1.86482e+006
1
1.85941e+006
1
1.84772e+006
1
1.84668e+006
1
1.85929e+006
1
1.87434e+006
1
1.8613e+006
1
1.87331e+006
1
1.87248e+006
1
1.88261e+006
1
1.87946e+006
1
1.90084e+006
1
1.94583e+006
1
1.94908e+006
1
1.95455e+006
1
1.97711e+006
1
1.97601e+006
1
1.99317e+006
1
2.01083e+006
1
2.02135e+006
1
2.04926e+006
1
2.07898e+006
1
2.11964e+006
1
2.16819e+006
1
2.18832e+006
1
2.24332e+006
1
2.28576e+006
1
2.3055e+006
1
2.34723e+006
1
2.38685e+006
1
2.42512e+006
1
2.47985e+006
1
2.5489e+006
1
2.58705e+006
1
2.65654e+006
1
2.67586e+006
1
2.71679e+006
1
2.75427e+006
1
2.76506e+006
1
2.80811e+006
1
2.78653e+006
1
2.76188e+006
1
2.76501e+006
1
2.68889e+006
1
2.63532e+006
1
2.57166e+006
1
2.51378e+006
1
2.43509e+006
1
2.36906e+006
1
2.30241e+006
1
2.25232e+006
1
2.1784e+006
1
2.13756e+006
1
2.10254e+006
1
2.0465e+006
1
2.02545e+006
1
1.99927e+006
1
1.95294e+006
1
1.93983e+006
1
1.91933e+006
1
1.89623e+006
1
1.87364e+006
1
1.84341e+006
1
1.84114e+006
1
1.83376e+006
1
1.80728e+006
1
1.79333e+006
1
1.78755e+006
1
1.76657e+006
1
1.75315e+006
1
1.73715e+006
1
1.73622e+006
1
1.71459e+006
1
1.71166e+006
1
1.71898e+006
1
1.71422e+006
1
1.73296e+006
1
1.69819e+006
1
1.71028e+006
1
1.71493e+006
1
1.71176e+006
1
1.73388e+006
1
1.73575e+006
1
1.73104e+006
1
1.74882e+006
1
1.73146e+006
1
1.77624e+006
1
1.7527e+006
1
1.76943e+006
1
1.76957e+006
1
1.80322e+006
1
1.77505e+006
1
1.78696e+006
1
1.78743e+006
1
1.77951e+006
1
1.80249e+006
1
1.80061e+006
1
1.78357e+006
1
1.7781e+006
1
1.76212e+006
1
1.75896e+006
1
1.74757e+006
1
1.72077e+006
1
1.72216e+006
1
1.71288e+006
1
1.68569e+006
1
1.67176e+006
1
1.67872e+006
1
1.63466e+006
1
1.63223e+006
1
1.63247e+006
1
1.60717e+006
1
1.5919e+006
1
1.5713e+006
1
1.56202e+006
1
1.55019e+006
1
1.5575e+006
1
1.54596e+006
1
1.51488e+006
1
1.51842e+006
1
1.53467e+006
1
1.52293e+006
1
1.5162e+006
1
1.52736e+006
1
1.54047e+006
1
1.56664e+006
1
1.56634e+006
1
1.58162e+006
1
1.58511e+006
1
1.57099e+006
1
1.58814e+006
1
1.5756e+006
1
1.57165e+006
1
1.52356e+006
1
1.50231e+006
1
Ge3s - 590eV
PbSe-GeS Annealed
2011
4
10
7
41
2
0
7
Casa Info Follows
0
0
0
0

Lens Mode = Transmission
XPS
1

590
1e+037
1e+037
1e+037
1e+037
1e+037
FAT
100
1e+037
1e+037
1e+037
1e+037
1e+037
1e+037
1e+037
Ge3s - 590eV

-1
Kinetic Energy
eV
400
0.1
2
Intensity
d
Transmission
d
pulse counting
400
1
1e+037
1e+037
1e+037
1e+037
0
402
0
1
0
1
507297
1
514596
1
504809
1
502261
1
512144
1
498894
1
498783
1
513891
1
503177
1
516529
1
516495
1
507211
1
511437
1
513826
1
513029
1
511947
1
506377
1
510702
1
512531
1
511759
1
512876
1
519584
1
508075
1
521937
1
516663
1
512286
1
516079
1
514351
1
516781
1
512344
1
521983
1
520880
1
531217
1
525545
1
515514
1
522128
1
525420
1
527719
1
525555
1
518650
1
529072
1
532663
1
524074
1
534627
1
525976
1
530887
1
524833
1
536774
1
532490
1
527829
1
528399
1
530705
1
523319
1
521429
1
523286
1
537556
1
529225
1
525823
1
525993
1
536912
1
534154
1
536255
1
536918
1
534620
1
538640
1
529342
1
531470
1
537205
1
536077
1
538880
1
541548
1
538006
1
540508
1
541419
1
545185
1
546839
1
531719
1
545479
1
542202
1
534626
1
550767
1
549407
1
539676
1
553607
1
552827
1
550100
1
553282
1
547730
1
561868
1
550433
1
549303
1
543607
1
545569
1
551023
1
557809
1
551405
1
552144
1
561612
1
563566
1
558616
1
553811
1
559165
1
566249
1
557091
1
560905
1
554602
1
552175
1
554737
1
548065
1
567041
1
559797
1
551940
1
567711
1
556376
1
559189
1
566601
1
565445
1
568296
1
561299
1
571122
1
562354
1
566517
1
572093
1
570507
1
563717
1
576724
1
571605
1
562400
1
561182
1
568719
1
569383
1
565503
1
569572
1
561941
1
558875
1
582196
1
570695
1
570750
1
568579
1
566345
1
568850
1
571674
1
575938
1
569027
1
568733
1
569482
1
561548
1
567383
1
574494
1
572452
1
571450
1
578477
1
568240
1
571924
1
565126
1
573199
1
573194
1
572354
1
576621
1
568619
1
582854
1
567784
1
570204
1
574767
1
569735
1
570356
1
576075
1
572720
1
576006
1
571190
1
572666
1
579806
1
566673
1
562165
1
572702
1
562804
1
565779
1
570087
1
564087
1
567049
1
565414
1
558520
1
556538
1
573798
1
566552
1
567719
1
563596
1
559641
1
552345
1
565433
1
561815
1
555258
1
554870
1
566272
1
561453
1
557231
1
558698
1
560576
1
563936
1
570434
1
558151
1
Ge3p - 590eV
PbSe-GeS Annealed
2011
4
10
7
41
2
0
7
Casa Info Follows
0
0
0
0

Lens Mode = Transmission
XPS
1

590
1e+037
1e+037
1e+037
1e+037
1e+037
FAT
100
1e+037
1e+037
1e+037
1e+037
1e+037
1e+037
1e+037
Ge3p - 590eV

-1
Kinetic Energy
eV
454
0.1
2
Intensity
d
Transmission
d
pulse counting
400
3
1e+037
1e+037
1e+037
1e+037
0
442
0
1
0
1
1.37395e+006
1
1.54585e+006
1
1.81757e+006
1
2.24383e+006
1
2.91518e+006
1
3.87272e+006
1
5.04888e+006
1
6.35658e+006
1
7.53761e+006
1
8.32035e+006
1
8.5255e+006
1
7.9997e+006
1
7.01232e+006
1
5.71433e+006
1
4.3743e+006
1
3.24856e+006
1
2.36654e+006
1
1.78563e+006
1
1.41155e+006
1
1.16035e+006
1
1.0393e+006
1
954545
1
910995
1
876083
1
852817
1
826748
1
828968
1
810067
1
808286
1
813249
1
800682
1
809335
1
820149
1
822296
1
821232
1
837906
1
855507
1
871553
1
887559
1
896185
1
930216
1
941398
1
959417
1
983055
1
1.01458e+006
1
1.00201e+006
1
1.02073e+006
1
1.02598e+006
1
1.01888e+006
1
1.02473e+006
1
1.01247e+006
1
982895
1
981800
1
956430
1
946177
1
927331
1
914443
1
892481
1
876100
1
868113
1
842780
1
839321
1
824437
1
820615
1
798496
1
786605
1
786780
1
790764
1
759732
1
764419
1
756806
1
754495
1
740951
1
730196
1
724409
1
708902
1
714801
1
706823
1
687621
1
686852
1
677665
1
668791
1
659118
1
655905
1
657815
1
642699
1
647083
1
625619
1
637681
1
619457
1
626889
1
620767
1
622861
1
625401
1
612897
1
611684
1
616371
1
607583
1
620624
1
614890
1
609027
1
609640
1
607460
1
610142
1
610528
1
613207
1
608882
1
612558
1
607726
1
603530
1
608730
1
602724
1
598066
1
606858
1
616335
1
599535
1
607045
1
606882
1
609571
1
611019
1
612157
1
611863
1
610819
1
611079
1
614107
1
608729
1
605768
1
610662
1
616709
1
619624
1
609640
1
607465
1
607526
1
618732
1
613525
1
608330
1
611649
1
610175
1
613663
1
607577
1
609017
1
613104
1
620452
1
615584
1
623677
1
618574
1
611278
1
611642
1
623479
1
614112
1
612469
1
616406
1
616496
1
624439
1
616257
1
615512
1
619213
1
611556
1
621298
1
619003
1
621207
1
619440
1
613487
1
613673
1
617884
1
617473
1
614709
1
623366
1
620622
1
623265
1
619185
1
622458
1
614079
1
607822
1
627065
1
617435
1
622577
1
622468
1
622195
1
627866
1
626328
1
622817
1
633607
1
639295
1
634182
1
634359
1
619738
1
630524
1
624118
1
634253
1
643944
1
636138
1
631056
1
648915
1
649928
1
646761
1
642410
1
648743
1
650138
1
646817
1
647482
1
657639
1
656186
1
657713
1
660061
1
658516
1
666168
1
666258
1
665392
1
673022
1
669650
1
683243
1
678591
1
671885
1
670524
1
670580
1
675822
1
672143
1
680009
1
690248
1
673809
1
Ge3d - 590eV
PbSe-GeS Annealed
2011
4
10
7
41
2
0
7
Casa Info Follows
0
0
0
0

Lens Mode = Transmission
XPS
1

590
1e+037
1e+037
1e+037
1e+037
1e+037
FAT
100
1e+037
1e+037
1e+037
1e+037
1e+037
1e+037
1e+037
Ge3d - 590eV

-1
Kinetic Energy
eV
552
0.05
2
Intensity
d
Transmission
d
pulse counting
400
2
1e+037
1e+037
1e+037
1e+037
0
562
0
1
0
1
105331
1
100393
1
104492
1
98998.1
1
101439
1
100623
1
96532.9
1
97800
1
103022
1
100923
1
103032
1
101887
1
103486
1
101597
1
102539
1
100695
1
100369
1
100340
1
102615
1
99320.5
1
97169.3
1
99382.4
1
98480
1
100278
1
99067.1
1
101369
1
98375.8
1
97581.8
1
97942.2
1
95664.3
1
96934.1
1
94760.4
1
97266.4
1
96206.3
1
98951.6
1
99754.1
1
97518.4
1
94835
1
95065.9
1
95758.6
1
94950.5
1
96404.8
1
96028.9
1
95612.2
1
93713
1
97062.3
1
95341.9
1
95446
1
95175.7
1
93838.3
1
92654.2
1
95554.4
1
92543
1
96155.6
1
98989.6
1
94236.7
1
94187.4
1
96687.8
1
94996.9
1
97272
1
94960.3
1
98228
1
93629.9
1
93061.1
1
93320.2
1
95974
1
95226.4
1
92830.2
1
95409.4
1
94079
1
96866.6
1
95943
1
94913.9
1
95781.1
1
95919.1
1
98584.2
1
95294
1
97038.3
1
97473.4
1
101444
1
101356
1
99520.4
1
100786
1
97576.1
1
98758.7
1
99903.3
1
99479.6
1
99830.1
1
104627
1
106120
1
106353
1
105294
1
104210
1
102333
1
106475
1
111123
1
112535
1
114345
1
116972
1
118686
1
121144
1
120605
1
124937
1
132353
1
134511
1
144727
1
150826
1
164558
1
177065
1
189572
1
213657
1
237668
1
256063
1
295812
1
322989
1
351446
1
382299
1
421670
1
447261
1
475009
1
493780
1
504263
1
506301
1
511298
1
502853
1
478973
1
464062
1
443315
1
419457
1
398366
1
370970
1
351021
1
340455
1
329427
1
334256
1
339893
1
356464
1
381225
1
412870
1
450170
1
494381
1
535897
1
582478
1
625933
1
646151
1
669080
1
699694
1
681897
1
685052
1
663686
1
640677
1
595026
1
547998
1
511423
1
456695
1
401120
1
354565
1
313310
1
264198
1
229524
1
203490
1
170972
1
148739
1
138686
1
121843
1
109240
1
100607
1
93914.3
1
87190.3
1
84135.3
1
82731.6
1
79620.3
1
74842
1
73372.2
1
71111.1
1
70625.4
1
72038.9
1
69019.1
1
68550.2
1
70218.6
1
68795.2
1
67143.8
1
65033.4
1
66517.3
1
64180.2
1
64616.7
1
66255.4
1
63621.3
1
63646.6
1
65348.8
1
60885.8
1
64390
1
64485.7
1
61726.3
1
62479.5
1
64729.3
1
63998.6
1
63101.8
1
63543.9
1
63525.6
1
61972.7
1
63049.7
1
61750.3
1
61730.5
1
61227.9
1
59047.2
1
60995.6
1
60732.4
1
60522.6
1
59237.2
1
60393.1
1
62361.3
1
58927.5
1
60584.5
1
63700.1
1
62521.8
1
61601
1
60980.2
1
61581.3
1
61726.3
1
61060.4
1
62607.6
1
60077.7
1
61470.1
1
59737
1
62268.4
1
63405.9
1
64318.2
1
60176.3
1
59775
1
61585.5
1
63969
1
61377.2
1
62976.5
1
64052.1
1
63459.4
1
62188.1
1
63940.9
1
65551.5
1
62868.1
1
64088.7
1
65029.2
1
65374.1
1
64066.2
1
62555.6
1
63532.6
1
65268.5
1
64436.5
1
63657.9
1
62607.6
1
64308.3
1
68751.6
1
68101.1
1
68151.8
1
64471.7
1
66528.5
1
69337.2
1
70303
1
67991.3
1
68508
1
72545.7
1
72265.6
1
69951.1
1
71829.1
1
71422.3
1
74042.3
1
72450
1
73887.4
1
72789.3
1
75032
1
76874.9
1
76055.5
1
74084.5
1
77463.4
1
77607
1
74294.3
1
78716.4
1
76938.3
1
79735.7
1
78463
1
79161.3
1
end of experiment